Workbook

Sheet Flujo de Caja
B1: Electro Dunas S.A.A. - Estado de Flujos de Efectivo
B2: Metodo indirecto, cifras acumuladas desde el 1 de enero de cada ano, en miles de soles. Fuente: nota de flujos de efectivo de cada EEFF.
B4: En miles de soles | C4: 2022 | D4: 2023 | E4: 2024 | F4: 1T 2025 | G4: 2T 2025 (6M) | H4: 3T 2025 (9M) | I4: 2025 | J4: 1T 2026 | K4: 2T 2026 (6M) | L4: 3T 2026 (9M) (proyectado) | M4: 2026 (proyectado) | N4: 1T 2027 (proyectado) | O4: 2T 2027 (6M) (proyectado) | P4: 3T 2027 (9M) (proyectado) | Q4: 2027 (proyectado)
B6: Actividades de operacion
B7: Utilidad neta del periodo | C7: 53638 | D7: 57645 | E7: 61658 | F7: 21162 | G7: 37718 | H7: 52755 | I7: 63359 | J7: 10796 | K7: 24917
B8: (+) Impuesto a las ganancias | C8: 23928 | D8: 25479 | E8: 27190 | F8: 8769 | G8: 15743 | H8: 22272 | I8: 27170 | J8: 5988 | K8: 12383
B9: (+) Estimacion de perdida esperada de CxC | C9: 3106 | D9: 4613 | E9: 2437 | F9: 244 | G9: 1011 | H9: 1344 | I9: 1408 | J9: -161 | K9: 165
B10: (+) Desvalorizacion de inventarios | C10: 0 | D10: 0 | E10: 0 | F10: 0 | G10: 0 | H10: 472 | I10: 472 | J10: 75 | K10: 79
B11: (+) Depreciacion | C11: 48094 | D11: 49569 | E11: 53367 | F11: 14574 | G11: 29178 | H11: 44134 | I11: 59328 | J11: 14997 | K11: 30669
B12: (+) Amortizacion | C12: 2340 | D12: 2056 | E12: 1278 | F12: 398 | G12: 797 | H12: 1197 | I12: 1835 | J12: 552 | K12: 1069
B13: (+/-) Estimaciones (reversiones) de provisiones | C13: -672 | D13: 1719 | E13: 1813 | F13: -560 | G13: -408 | H13: -65 | I13: -25 | J13: 288 | K13: 1086
B14: (+) Baja de PP&E e intangibles | C14: 740 | D14: 1058 | E14: 1093 | F14: 233 | G14: 438 | H14: 650 | I14: 840 | J14: 295 | K14: 598
B15: (-) Ingresos financieros | C15: -5557 | D15: -5630 | E15: -4622 | F15: -1394 | G15: -2610 | H15: -3685 | I15: -4824 | J15: -997 | K15: -1863
B16: (+) Gastos financieros | C16: 26463 | D16: 26995 | E16: 28692 | F16: 6694 | G16: 15431 | H16: 23119 | I16: 31380 | J16: 7721 | K16: 15363
B17: (+/-) Perdida (ganancia) por diferencia de cambio | C17: -1268 | D17: 154 | E17: 1124 | F17: 0 | G17: 0 | H17: 0 | I17: -6977 | J17: 0 | K17: 0
B19: Cambios en activos y pasivos operativos
B20: Var. cuentas por cobrar comerciales | C20: -14602 | D20: -1062 | E20: -4712 | F20: 614 | G20: 6400 | H20: 7502 | I20: 3839 | J20: -769 | K20: -3173
B21: Var. cuentas por cobrar a relacionadas | C21: 450 | D21: -143 | E21: -816 | F21: 247 | G21: 314 | H21: 28 | I21: -178 | J21: 279 | K21: -502
B22: Var. otras cuentas por cobrar | C22: 2074 | D22: -310 | E22: 176 | F22: -178 | G22: -173 | H22: -665 | I22: -3876 | J22: 79 | K22: 1019
B23: Var. inventarios | C23: 698 | D23: -226 | E23: -1868 | F23: -244 | G23: -2210 | H23: -2872 | I23: -4985 | J23: 489 | K23: -3297
B24: Var. otros activos no financieros | C24: -1945 | D24: 72 | E24: -1747 | F24: 307 | G24: 797 | H24: 2023 | I24: -737 | J24: 458 | K24: 28
B25: Var. cuentas por pagar comerciales | C25: 13614 | D25: -15466 | E25: 1150 | F25: 1293 | G25: -7506 | H25: -7728 | I25: 8671 | J25: -16506 | K25: -19050
B26: Var. cuentas por pagar a relacionadas | C26: 4404 | D26: 5024 | E26: -4113 | F26: -3798 | G26: -4638 | H26: -2388 | I26: 1499 | J26: 1759 | K26: -2420
B27: Var. pasivo por arrendamiento (NIIF 16) | C27: 0 | D27: 0 | E27: 0 | F27: -174 | G27: -388 | H27: -511 | I27: 0 | J27: 160 | K27: 0
B28: Var. otras cuentas por pagar | C28: -5595 | D28: -1711 | E28: -1571 | F28: -2028 | G28: -2748 | H28: -1081 | I28: -4449 | J28: 3694 | K28: 1272
B29: Efectivo generado por operaciones | C29: =C7+C8+C9+C10+C11+C12+C13+C14+C15+C16+C17+C20+C21+C22+C23+C24+C25+C26+C27+C28 -> 149910 | D29: =D7+D8+D9+D10+D11+D12+D13+D14+D15+D16+D17+D20+D21+D22+D23+D24+D25+D26+D27+D28 -> 149836 | E29: =E7+E8+E9+E10+E11+E12+E13+E14+E15+E16+E17+E20+E21+E22+E23+E24+E25+E26+E27+E28 -> 160529 | F29: =F7+F8+F9+F10+F11+F12+F13+F14+F15+F16+F17+F20+F21+F22+F23+F24+F25+F26+F27+F28 -> 46159 | G29: =G7+G8+G9+G10+G11+G12+G13+G14+G15+G16+G17+G20+G21+G22+G23+G24+G25+G26+G27+G28 -> 87146 | H29: =H7+H8+H9+H10+H11+H12+H13+H14+H15+H16+H17+H20+H21+H22+H23+H24+H25+H26+H27+H28 -> 136501 | I29: =I7+I8+I9+I10+I11+I12+I13+I14+I15+I16+I17+I20+I21+I22+I23+I24+I25+I26+I27+I28 -> 173750 | J29: =J7+J8+J9+J10+J11+J12+J13+J14+J15+J16+J17+J20+J21+J22+J23+J24+J25+J26+J27+J28 -> 29197 | ... Q29: =Q7+Q8+Q9+Q10+Q11+Q12+Q13+Q14+Q15+Q16+Q17+Q20+Q21+Q22+Q23+Q24+Q25+Q26+Q27+Q28 -> 0
B30: Intereses cobrados | C30: 4818 | D30: 5336 | E30: 4309 | F30: 819 | G30: 2149 | H30: 2946 | I30: 4088 | J30: 831 | K30: 1643
B31: Impuesto a las ganancias pagado | C31: -17647 | D31: -24569 | E31: -25172 | F31: -6986 | G31: -13651 | H31: -19777 | I31: -26105 | J31: -6575 | K31: -9565
B32: Flujo neto de actividades de operacion | C32: =C29+C30+C31 -> 137081 | D32: =D29+D30+D31 -> 130603 | E32: =E29+E30+E31 -> 139666 | F32: =F29+F30+F31 -> 39992 | G32: =G29+G30+G31 -> 75644 | H32: =H29+H30+H31 -> 119670 | I32: =I29+I30+I31 -> 151733 | J32: =J29+J30+J31 -> 23453 | ... Q32: =Q29+Q30+Q31 -> 0
B34: Actividades de inversion
B35: Adquisicion de propiedad, planta y equipo | C35: -50329 | D35: -71429 | E35: -80791 | F35: -14971 | G35: -40597 | H35: -73400 | I35: -107078 | J35: -15177 | K35: -34417
B36: Adquisicion de activos intangibles | C36: -2575 | D36: -2410 | E36: -7319 | F36: -260 | G36: -942 | H36: -1380 | I36: -2235 | J36: -647 | K36: -2468
B37: Prestamos otorgados a entidades relacionadas | C37: 0 | D37: -10046 | E37: -1200 | F37: 0 | G37: 0 | H37: 0 | I37: 0 | J37: 0 | K37: 0
B38: Devolucion de prestamos otorgados a relacionadas | C38: 0 | D38: 25667 | E38: 2800 | F38: 0 | G38: 0 | H38: 10622 | I38: 15622 | J38: 0 | K38: 0
B39: Flujo neto de actividades de inversion | C39: =C35+C36+C37+C38 -> -52904 | D39: =D35+D36+D37+D38 -> -58218 | E39: =E35+E36+E37+E38 -> -86510 | F39: =F35+F36+F37+F38 -> -15231 | G39: =G35+G36+G37+G38 -> -41539 | H39: =H35+H36+H37+H38 -> -64158 | I39: =I35+I36+I37+I38 -> -93691 | J39: =J35+J36+J37+J38 -> -15824 | ... Q39: =Q35+Q36+Q37+Q38 -> 0
B41: Actividades de financiamiento
B42: Ingreso de deudas y prestamos que devengan interes | C42: 64470 | D42: 85635 | E42: 286000 | F42: 170000 | G42: 195000 | H42: 230000 | I42: 355000 | J42: 10000 | K42: 170000
B43: Obtencion de prestamos de entidades relacionadas | C43: 0 | D43: 42477 | E43: 0 | F43: 0 | G43: 0 | H43: 0 | I43: 0 | J43: 0 | K43: 0
B44: Pago de pasivo por arrendamiento (NIIF 16) | C44: -30923 | D44: -34065 | E44: -37955 | F44: -11200 | G44: -22415 | H44: -33874 | I44: -45210 | J44: -11545 | K44: -23656
B45: Pago de deudas y prestamos que devengan interes | C45: -136586 | D45: -102870 | E45: -226000 | F45: -160000 | G45: -160000 | H45: -185000 | I45: -265500 | J45: -10000 | K45: -135000
...

Sheet Situacion Financiera
B1: Electro Dunas S.A.A. - Estado de Situacion Financiera
B2: Saldos a la fecha de cierre de cada periodo, en miles de soles.
B4: En miles de soles | C4: 2022 | D4: 2023 | E4: 2024 | F4: 1T 2025 | G4: 2T 2025 (6M) | H4: 3T 2025 (9M) | I4: 2025 | J4: 1T 2026 | K4: 2T 2026 (6M) | L4: 3T 2026 (9M) (proyectado) | M4: 2026 (proyectado) | N4: 1T 2027 (proyectado) | O4: 2T 2027 (6M) (proyectado) | P4: 3T 2027 (9M) (proyectado) | Q4: 2027 (proyectado)
B5: Activo
B6: Efectivo | C6: 18488 | D6: 16159 | E6: 10132 | F6: 13404 | G6: 29192 | H6: 19720 | I6: 25510 | J6: 18213 | K6: 20264
B7: Cuentas por cobrar comerciales | C7: 87655 | D7: 84151 | E7: 86431 | F7: 85574 | G7: 79021 | H7: 77588 | I7: 81197 | J7: 82127 | K7: 84205
B8: Cuentas por cobrar a relacionadas | C8: 44547 | D8: 2711 | E8: 27406 | F8: 27333 | G8: 27029 | H8: 16824 | I8: 11855 | J8: 11612 | K8: 12320
B9: Otras cuentas por cobrar | C9: 2574 | D9: 2883 | E9: 2664 | F9: 2846 | G9: 2846 | H9: 3547 | I9: 6716 | J9: 6632 | K9: 5695
B10: Inventarios | C10: 4566 | D10: 4795 | E10: 6668 | F10: 6912 | G10: 8878 | H10: 9069 | I10: 11173 | J10: 10608 | K10: 14390
B11: Otros activos no financieros | C11: 4135 | D11: 4017 | E11: 5722 | F11: 5404 | G11: 4902 | H11: 3664 | I11: 6416 | J11: 5952 | K11: 6378
B12: Total activos corrientes | C12: =SUM(C6:C11) -> 161965 | D12: =SUM(D6:D11) -> 114716 | E12: =SUM(E6:E11) -> 139023 | F12: =SUM(F6:F11) -> 141473 | G12: =SUM(G6:G11) -> 151868 | H12: =SUM(H6:H11) -> 130412 | I12: =SUM(I6:I11) -> 142867 | J12: =SUM(J6:J11) -> 135144 | ... Q12: =SUM(Q6:Q11) -> 0
B14: Activo no corriente
B15: Otras cuentas por cobrar, neto | C15: 391 | D15: 364 | E15: 366 | F15: 363 | G15: 357 | H15: 148 | I15: 143 | J15: 149 | K15: 146
B16: Cuentas por cobrar a relacionadas | C16: 13048 | D16: 39588 | E16: 14385 | F16: 14490 | G16: 14597 | H16: 14706 | I16: 14816 | J16: 14925 | K16: 15035
B17: Propiedad, planta y equipo | C17: 518774 | D17: 573565 | E17: 639383 | F17: 654531 | G17: 673417 | H17: 701260 | I17: 730426 | J17: 746100 | K17: 761918
B18: Activo por derecho de uso | C18: 111157 | D18: 88938 | E18: 118201 | F18: 110832 | G18: 103511 | H18: 96362 | I18: 88963 | J18: 81631 | K18: 75915
B19: Activos intangibles | C19: 8493 | D19: 8847 | E19: 14888 | F19: 14136 | G19: 15033 | H19: 15071 | I19: 15288 | J19: 15383 | K19: 16687
B20: Total activos no corrientes | C20: =SUM(C15:C19) -> 651863 | D20: =SUM(D15:D19) -> 711302 | E20: =SUM(E15:E19) -> 787223 | F20: =SUM(F15:F19) -> 794352 | G20: =SUM(G15:G19) -> 806915 | H20: =SUM(H15:H19) -> 827547 | I20: =SUM(I15:I19) -> 849636 | J20: =SUM(J15:J19) -> 858188 | ... Q20: =SUM(Q15:Q19) -> 0
B21: TOTAL ACTIVOS | C21: =C12+C20 -> 813828 | D21: =D12+D20 -> 826018 | E21: =E12+E20 -> 926246 | F21: =F12+F20 -> 935825 | G21: =G12+G20 -> 958783 | H21: =H12+H20 -> 957959 | I21: =I12+I20 -> 992503 | J21: =J12+J20 -> 993332 | ... Q21: =Q12+Q20 -> 0
B23: Pasivo
B24: Pasivo corriente
B25: Otros pasivos financieros | C25: 39581 | D25: 21226 | E25: 146516 | F25: 158063 | G25: 182173 | H25: 194528 | I25: 137330 | J25: 141070 | K25: 274421
B26: Pasivo por arrendamiento | C26: 24195 | D26: 28429 | E26: 34392 | F26: 35285 | G26: 36236 | H26: 37269 | I26: 38094 | J26: 34247 | K26: 31110
B27: Cuentas por pagar comerciales | C27: 53792 | D27: 43989 | E27: 52610 | F27: 60056 | G27: 51029 | H27: 52162 | I27: 70205 | J27: 60850 | K27: 60528
B28: Cuentas por pagar a relacionadas | C28: 12024 | D28: 61022 | E28: 13914 | F28: 10490 | G28: 36829 | H28: 14275 | I28: 14942 | J28: 30975 | K28: 31963
B29: Pasivos por impuesto a las ganancias | C29: 1307 | D29: 964 | E29: 2131 | F29: 3697 | G29: 3237 | H29: 3375 | I29: 22 | J29: 635 | K29: 0
B30: Provision para beneficio de empleados | C30: 9228 | D30: 8618 | E30: 8933 | F30: 7913 | G30: 8305 | H30: 9557 | I30: 9847 | J30: 8062 | K30: 8201
B31: Otras cuentas por pagar | C31: 6675 | D31: 7645 | E31: 8552 | F31: 5462 | G31: 4425 | H31: 6472 | I31: 3398 | J31: 7217 | K31: 5886
B32: Provisiones | C32: 775 | D32: 786 | E32: 642 | F32: 1984 | G32: 2869 | H32: 3655 | I32: 1355 | J32: 1161 | K32: 1771
B33: Total pasivos corrientes | C33: =SUM(C25:C32) -> 147577 | D33: =SUM(D25:D32) -> 172679 | E33: =SUM(E25:E32) -> 267690 | F33: =SUM(F25:F32) -> 282950 | G33: =SUM(G25:G32) -> 325103 | H33: =SUM(H25:H32) -> 321293 | I33: =SUM(I25:I32) -> 275193 | J33: =SUM(J25:J32) -> 284217 | ... Q33: =SUM(Q25:Q32) -> 0
B35: Pasivo no corriente
B36: Otros pasivos financieros | C36: 295391 | D36: 295110 | E36: 229798 | F36: 229821 | G36: 229847 | H36: 229886 | I36: 330317 | J36: 331540 | K36: 229973
B37: Pasivo por arrendamiento | C37: 122030 | D37: 95381 | E37: 115294 | F37: 105872 | G37: 96215 | H37: 86601 | I37: 76718 | J37: 71401 | K37: 66503
B38: Cuentas por pagar a relacionadas | C38: 302 | D38: 271 | E38: 43981 | F38: 42897 | G38: 41390 | H38: 40539 | I38: 39266 | J38: 40746 | K38: 39799
B39: Otras cuentas por pagar | C39: 13699 | D39: 15026 | E39: 19472 | F39: 22234 | G39: 22828 | H39: 22824 | I39: 22471 | J39: 22640 | K39: 23637
B40: Provisiones | C40: 10216 | D40: 10728 | E40: 10028 | F40: 7882 | G40: 6904 | H40: 5019 | I40: 6193 | J40: 5460 | K40: 5603
B41: Pasivos por impuestos diferidos | C41: 29208 | D41: 30462 | E41: 31312 | F41: 31528 | G41: 32299 | H41: 32563 | I41: 34486 | J41: 35053 | K41: 37162
B42: Beneficios a los empleados | C42: 0 | D42: 186 | E42: 0 | F42: 0 | G42: 0 | H42: 0 | I42: 0 | J42: 0 | K42: 0
B43: Total pasivos no corrientes | C43: =SUM(C36:C42) -> 470846 | D43: =SUM(D36:D42) -> 447164 | E43: =SUM(E36:E42) -> 449885 | F43: =SUM(F36:F42) -> 440234 | G43: =SUM(G36:G42) -> 429483 | H43: =SUM(H36:H42) -> 417432 | I43: =SUM(I36:I42) -> 509451 | J43: =SUM(J36:J42) -> 506840 | ... Q43: =SUM(Q36:Q42) -> 0
B44: TOTAL PASIVOS | C44: =C33+C43 -> 618423 | D44: =D33+D43 -> 619843 | E44: =E33+E43 -> 717575 | F44: =F33+F43 -> 723184 | G44: =G33+G43 -> 754586 | H44: =H33+H43 -> 738725 | I44: =I33+I43 -> 784644 | J44: =J33+J43 -> 791057 | ... Q44: =Q33+Q43 -> 0
...

Sheet Resultados
B1: Electro Dunas S.A.A. - Estado de Resultados
B2: Cifras acumuladas desde el 1 de enero de cada ano, en miles de soles, tal como las reporta la Companhia. Columnas en amarillo: pendientes de completar.
B4: En miles de soles | C4: 2022 | D4: 2023 | E4: 2024 | F4: 1T 2025 | G4: 2T 2025 (6M) | H4: 3T 2025 (9M) | I4: 2025 | J4: 1T 2026 | K4: 2T 2026 (6M) | L4: 3T 2026 (9M) (proyectado) | M4: 2026 (proyectado) | N4: 1T 2027 (proyectado) | O4: 2T 2027 (6M) (proyectado) | P4: 3T 2027 (9M) (proyectado) | Q4: 2027 (proyectado)
B6: Ingresos por servicio de distribucion de energia | C6: 480828 | D6: 531848 | E6: 562856 | F6: 152327 | G6: 293272 | H6: 429410 | I6: 573857 | J6: 148162 | K6: 293216
B7: Otros ingresos operativos | C7: 7755 | D7: 8905 | E7: 7667 | F7: 1847 | G7: 3864 | H7: 5802 | I7: 7564 | J7: 1856 | K7: 4117
B8: Total ingresos operativos | C8: =C6+C7 -> 488583 | D8: =D6+D7 -> 540753 | E8: =E6+E7 -> 570523 | F8: =F6+F7 -> 154174 | G8: =G6+G7 -> 297136 | H8: =H6+H7 -> 435212 | I8: =I6+I7 -> 581421 | J8: =J6+J7 -> 150018 | ... Q8: =Q6+Q7 -> 0
B9: Costo de servicio de distribucion de energia | C9: -322814 | D9: -361629 | E9: -386573 | F9: -103761 | G9: -199386 | H9: -292098 | I9: -398594 | J9: -106468 | K9: -210941
B10: Otros costos operativos | C10: -235 | D10: -158 | E10: -200 | F10: -16 | G10: -120 | H10: -179 | I10: -247 | J10: -73 | K10: -120
B11: Total costos operativos | C11: =C9+C10 -> -323049 | D11: =D9+D10 -> -361787 | E11: =E9+E10 -> -386773 | F11: =F9+F10 -> -103777 | G11: =G9+G10 -> -199506 | H11: =H9+H10 -> -292277 | I11: =I9+I10 -> -398841 | J11: =J9+J10 -> -106541 | ... Q11: =Q9+Q10 -> 0
B12: Utilidad bruta | C12: =C8+C11 -> 165534 | D12: =D8+D11 -> 178966 | E12: =E8+E11 -> 183750 | F12: =F8+F11 -> 50397 | G12: =G8+G11 -> 97630 | H12: =H8+H11 -> 142935 | I12: =I8+I11 -> 182580 | J12: =J8+J11 -> 43477 | ... Q12: =Q8+Q11 -> 0
B13: Margen bruto | C13: =IFERROR(C12/C8,"") -> 0.33880426 | D13: =IFERROR(D12/D8,"") -> 0.33095702 | E13: =IFERROR(E12/E8,"") -> 0.32207291 | F13: =IFERROR(F12/F8,"") -> 0.32688391 | G13: =IFERROR(G12/G8,"") -> 0.32857008 | H13: =IFERROR(H12/H8,"") -> 0.32842615 | I13: =IFERROR(I12/I8,"") -> 0.31402375 | J13: =IFERROR(J12/J8,"") -> 0.28981189 | ... Q13: =IFERROR(Q12/Q8,"")
B15: Gastos de comercializacion | C15: -36038 | D15: -35653 | E15: -30427 | F15: -7813 | G15: -16044 | H15: -23888 | I15: -30840 | J15: -8210 | K15: -15609
B16: Gastos de administracion | C16: -34720 | D16: -35719 | E16: -38860 | F16: -10103 | G16: -20865 | H16: -31410 | I16: -44184 | J16: -10755 | K16: -20259
B17: Perdida por deterioro de cuentas por cobrar | C17: -1807 | D17: -4600 | E17: -2437 | F17: -244 | G17: -1011 | H17: -1344 | I17: -1392 | J17: 161 | K17: -165
B18: Otros ingresos | C18: 9405 | D18: 6393 | E18: 7928 | F18: 2700 | G18: 4575 | H18: 5957 | I18: 7959 | J18: 2129 | K18: 4954
B19: Otros gastos | C19: -5170 | D19: -4744 | E19: -5912 | F19: -1281 | G19: -2165 | H19: -3173 | I19: -4015 | J19: -1331 | K19: -3466
B20: Total gastos operativos | C20: =C15+C16+C17+C18+C19 -> -68330 | D20: =D15+D16+D17+D18+D19 -> -74323 | E20: =E15+E16+E17+E18+E19 -> -69708 | F20: =F15+F16+F17+F18+F19 -> -16741 | G20: =G15+G16+G17+G18+G19 -> -35510 | H20: =H15+H16+H17+H18+H19 -> -53858 | I20: =I15+I16+I17+I18+I19 -> -72472 | J20: =J15+J16+J17+J18+J19 -> -18006 | ... Q20: =Q15+Q16+Q17+Q18+Q19 -> 0
B21: Utilidad operativa (EBIT) | C21: =C12+C20 -> 97204 | D21: =D12+D20 -> 104643 | E21: =E12+E20 -> 114042 | F21: =F12+F20 -> 33656 | G21: =G12+G20 -> 62120 | H21: =H12+H20 -> 89077 | I21: =I12+I20 -> 110108 | J21: =J12+J20 -> 25471 | ... Q21: =Q12+Q20 -> 0
B22: Margen operativo | C22: =IFERROR(C21/C8,"") -> 0.19895084 | D22: =IFERROR(D21/D8,"") -> 0.19351349 | E22: =IFERROR(E21/E8,"") -> 0.19989028 | F22: =IFERROR(F21/F8,"") -> 0.21829881 | G22: =IFERROR(G21/G8,"") -> 0.20906252 | H22: =IFERROR(H21/H8,"") -> 0.20467496 | I22: =IFERROR(I21/I8,"") -> 0.1893774 | J22: =IFERROR(J21/J8,"") -> 0.16978629 | ... Q22: =IFERROR(Q21/Q8,"")
B23: (+) Depreciacion y amortizacion del periodo | C23: ='Flujo de Caja'!C11+'Flujo de Caja'!C12 -> 50434 | D23: ='Flujo de Caja'!D11+'Flujo de Caja'!D12 -> 51625 | E23: ='Flujo de Caja'!E11+'Flujo de Caja'!E12 -> 54645 | F23: ='Flujo de Caja'!F11+'Flujo de Caja'!F12 -> 14972 | G23: ='Flujo de Caja'!G11+'Flujo de Caja'!G12 -> 29975 | H23: ='Flujo de Caja'!H11+'Flujo de Caja'!H12 -> 45331 | I23: ='Flujo de Caja'!I11+'Flujo de Caja'!I12 -> 61163 | J23: ='Flujo de Caja'!J11+'Flujo de Caja'!J12 -> 15549 | ... Q23: ='Flujo de Caja'!Q11+'Flujo de Caja'!Q12 -> 0
B24: EBITDA | C24: =C21+C23 -> 147638 | D24: =D21+D23 -> 156268 | E24: =E21+E23 -> 168687 | F24: =F21+F23 -> 48628 | G24: =G21+G23 -> 92095 | H24: =H21+H23 -> 134408 | I24: =I21+I23 -> 171271 | J24: =J21+J23 -> 41020 | ... Q24: =Q21+Q23 -> 0
B25: Margen EBITDA | C25: =IFERROR(C24/C8,"") -> 0.30217588 | D25: =IFERROR(D24/D8,"") -> 0.28898222 | E25: =IFERROR(E24/E8,"") -> 0.29567081 | F25: =IFERROR(F24/F8,"") -> 0.31540986 | G25: =IFERROR(G24/G8,"") -> 0.30994225 | H25: =IFERROR(H24/H8,"") -> 0.3088334 | I25: =IFERROR(I24/I8,"") -> 0.29457312 | J25: =IFERROR(J24/J8,"") -> 0.27343385 | ... Q25: =IFERROR(Q24/Q8,"")
B27: Ingresos financieros | C27: 5557 | D27: 5630 | E27: 4622 | F27: 1394 | G27: 2610 | H27: 3685 | I27: 4824 | J27: 997 | K27: 1863
B28: Gastos financieros | C28: -26463 | D28: -26995 | E28: -28692 | F28: -6694 | G28: -15431 | H28: -23119 | I28: -31380 | J28: -7721 | K28: -15363
B29: Diferencia de cambio, neta | C29: 1268 | D29: -154 | E29: -1124 | F29: 1575 | G29: 4162 | H29: 5384 | I29: 6977 | J29: -1963 | K29: -927
B30: Costo financiero neto | C30: =C27+C28+C29 -> -19638 | D30: =D27+D28+D29 -> -21519 | E30: =E27+E28+E29 -> -25194 | F30: =F27+F28+F29 -> -3725 | G30: =G27+G28+G29 -> -8659 | H30: =H27+H28+H29 -> -14050 | I30: =I27+I28+I29 -> -19579 | J30: =J27+J28+J29 -> -8687 | ... Q30: =Q27+Q28+Q29 -> 0
B31: Utilidad antes de impuesto a las ganancias | C31: =C21+C30 -> 77566 | D31: =D21+D30 -> 83124 | E31: =E21+E30 -> 88848 | F31: =F21+F30 -> 29931 | G31: =G21+G30 -> 53461 | H31: =H21+H30 -> 75027 | I31: =I21+I30 -> 90529 | J31: =J21+J30 -> 16784 | ... Q31: =Q21+Q30 -> 0
B32: Gasto por impuesto a las ganancias | C32: -23928 | D32: -25479 | E32: -27190 | F32: -8769 | G32: -15743 | H32: -22272 | I32: -27170 | J32: -5988 | K32: -12383
B33: Utilidad neta | C33: =C31+C32 -> 53638 | D33: =D31+D32 -> 57645 | E33: =E31+E32 -> 61658 | F33: =F31+F32 -> 21162 | G33: =G31+G32 -> 37718 | H33: =H31+H32 -> 52755 | I33: =I31+I32 -> 63359 | J33: =J31+J32 -> 10796 | ... Q33: =Q31+Q32 -> 0
B34: Margen neto | C34: =IFERROR(C33/C8,"") -> 0.10978278 | D34: =IFERROR(D33/D8,"") -> 0.10660135 | E34: =IFERROR(E33/E8,"") -> 0.10807277 | F34: =IFERROR(F33/F8,"") -> 0.1372605 | G34: =IFERROR(G33/G8,"") -> 0.12693851 | H34: =IFERROR(H33/H8,"") -> 0.12121679 | I34: =IFERROR(I33/I8,"") -> 0.10897267 | J34: =IFERROR(J33/J8,"") -> 0.071964698 | ... Q34: =IFERROR(Q33/Q8,"")
B35: Control: Utilidad neta (Resultados) vs Utilidad neta (Flujo de Caja), debe ser 0 | C35: =IF(ISBLANK(C6),"",C33-'Flujo de Caja'!C7) -> 0 | D35: =IF(ISBLANK(D6),"",D33-'Flujo de Caja'!D7) -> 0 | E35: =IF(ISBLANK(E6),"",E33-'Flujo de Caja'!E7) -> 0 | F35: =IF(ISBLANK(F6),"",F33-'Flujo de Caja'!F7) -> 0 | G35: =IF(ISBLANK(G6),"",G33-'Flujo de Caja'!G7) -> 0 | H35: =IF(ISBLANK(H6),"",H33-'Flujo de Caja'!H7) -> 0 | I35: =IF(ISBLANK(I6),"",I33-'Flujo de Caja'!I7) -> 0 | J35: =IF(ISBLANK(J6),"",J33-'Flujo de Caja'!J7) -> 0 | ... Q35: =IF(ISBLANK(Q6),"",Q33-'Flujo de Caja'!Q7)
B37: Utilidad neta por accion basica y diluida (S/) | C37: 0.315 | D37: 0.339 | E37: 0.362 | F37: 0.124 | G37: 0.222 | H37: 0.31 | I37: 0.372 | J37: 0.063 | K37: 0.146

Sheet Trimestres
B1: Electro Dunas S.A.A. - Trimestre Aislado (no acumulado)
B2: Cada trimestre calculado como la diferencia entre acumulados consecutivos (2T-1T, 3T-2T, 4T-3T). En miles de soles.
B4: Datos base 2024 - acumulado desde el 1 de enero (columnas comparativas de los EEFF intermedios 1T/2T/3T 2025)
B5: En miles de soles | C5: 3M24 | D5: 6M24 | E5: 9M24
B6: Ingresos totales operativos | C6: 151655 | D6: 291627 | E6: 422622
B7: Utilidad bruta | C7: 50187 | D7: 97911 | E7: 138388
B8: Utilidad operativa (EBIT) | C8: 32945 | D8: 61760 | E8: 85900
B9: EBITDA | C9: 45761 | D9: 87922 | E9: 125844
B10: Utilidad neta | C10: 18247 | D10: 32663 | E10: 47649
B11: Flujo neto de operacion | C11: 20922 | D11: 66183 | E11: 104420
B12: Capex (PP&E + intangibles) | C12: -13366 | D12: -42178 | E12: -63955
B14: FY2024 (acumulado 12 meses, hoja Resultados/Flujo de Caja)
B16: En miles de soles | C16: 1T 2024 | D16: 2T 2024 | E16: 3T 2024 | F16: 4T 2024 | G16: 1T 2025 | H16: 2T 2025 | I16: 3T 2025 | J16: 4T 2025 | K16: 1T 2026 | L16: 2T 2026 | M16: 3T 2026 (proyectado) | N16: 4T 2026 (proyectado)
B17: Ingresos totales operativos | C17: =IF(C6=0,"",C6) -> 151655 | D17: =IF(D6=0,"",D6-(C6)) -> 139972 | E17: =IF(E6=0,"",E6-(D6)) -> 130995 | F17: =IF(Resultados!E8=0,"",Resultados!E8-(E6)) -> 147901 | G17: =IF(Resultados!F8=0,"",Resultados!F8) -> 154174 | H17: =IF(Resultados!G8=0,"",Resultados!G8-(Resultados!F8)) -> 142962 | I17: =IF(Resultados!H8=0,"",Resultados!H8-(Resultados!G8)) -> 138076 | J17: =IF(Resultados!I8=0,"",Resultados!I8-(Resultados!H8)) -> 146209 | K17: =IF(Resultados!J8=0,"",Resultados!J8) -> 150018 | L17: =IF(Resultados!K8=0,"",Resultados!K8-(Resultados!J8)) -> 147315 | M17: =IF(Resultados!L8=0,"",Resultados!L8-(Resultados!K8)) | N17: =IF(Resultados!M8=0,"",Resultados!M8-(Resultados!L8))
B18: Utilidad bruta | C18: =IF(C7=0,"",C7) -> 50187 | D18: =IF(D7=0,"",D7-(C7)) -> 47724 | E18: =IF(E7=0,"",E7-(D7)) -> 40477 | F18: =IF(Resultados!E12=0,"",Resultados!E12-(E7)) -> 45362 | G18: =IF(Resultados!F12=0,"",Resultados!F12) -> 50397 | H18: =IF(Resultados!G12=0,"",Resultados!G12-(Resultados!F12)) -> 47233 | I18: =IF(Resultados!H12=0,"",Resultados!H12-(Resultados!G12)) -> 45305 | J18: =IF(Resultados!I12=0,"",Resultados!I12-(Resultados!H12)) -> 39645 | K18: =IF(Resultados!J12=0,"",Resultados!J12) -> 43477 | L18: =IF(Resultados!K12=0,"",Resultados!K12-(Resultados!J12)) -> 42795 | M18: =IF(Resultados!L12=0,"",Resultados!L12-(Resultados!K12)) | N18: =IF(Resultados!M12=0,"",Resultados!M12-(Resultados!L12))
B19: Utilidad operativa (EBIT) | C19: =IF(C8=0,"",C8) -> 32945 | D19: =IF(D8=0,"",D8-(C8)) -> 28815 | E19: =IF(E8=0,"",E8-(D8)) -> 24140 | F19: =IF(Resultados!E21=0,"",Resultados!E21-(E8)) -> 28142 | G19: =IF(Resultados!F21=0,"",Resultados!F21) -> 33656 | H19: =IF(Resultados!G21=0,"",Resultados!G21-(Resultados!F21)) -> 28464 | I19: =IF(Resultados!H21=0,"",Resultados!H21-(Resultados!G21)) -> 26957 | J19: =IF(Resultados!I21=0,"",Resultados!I21-(Resultados!H21)) -> 21031 | K19: =IF(Resultados!J21=0,"",Resultados!J21) -> 25471 | L19: =IF(Resultados!K21=0,"",Resultados!K21-(Resultados!J21)) -> 26256 | M19: =IF(Resultados!L21=0,"",Resultados!L21-(Resultados!K21)) | N19: =IF(Resultados!M21=0,"",Resultados!M21-(Resultados!L21))
B20: EBITDA | C20: =IF(C9=0,"",C9) -> 45761 | D20: =IF(D9=0,"",D9-(C9)) -> 42161 | E20: =IF(E9=0,"",E9-(D9)) -> 37922 | F20: =IF(Resultados!E24=0,"",Resultados!E24-(E9)) -> 42843 | G20: =IF(Resultados!F24=0,"",Resultados!F24) -> 48628 | H20: =IF(Resultados!G24=0,"",Resultados!G24-(Resultados!F24)) -> 43467 | I20: =IF(Resultados!H24=0,"",Resultados!H24-(Resultados!G24)) -> 42313 | J20: =IF(Resultados!I24=0,"",Resultados!I24-(Resultados!H24)) -> 36863 | K20: =IF(Resultados!J24=0,"",Resultados!J24) -> 41020 | L20: =IF(Resultados!K24=0,"",Resultados!K24-(Resultados!J24)) -> 42445 | M20: =IF(Resultados!L24=0,"",Resultados!L24-(Resultados!K24)) | N20: =IF(Resultados!M24=0,"",Resultados!M24-(Resultados!L24))
B21: Utilidad neta | C21: =IF(C10=0,"",C10) -> 18247 | D21: =IF(D10=0,"",D10-(C10)) -> 14416 | E21: =IF(E10=0,"",E10-(D10)) -> 14986 | F21: =IF(Resultados!E33=0,"",Resultados!E33-(E10)) -> 14009 | G21: =IF(Resultados!F33=0,"",Resultados!F33) -> 21162 | H21: =IF(Resultados!G33=0,"",Resultados!G33-(Resultados!F33)) -> 16556 | I21: =IF(Resultados!H33=0,"",Resultados!H33-(Resultados!G33)) -> 15037 | J21: =IF(Resultados!I33=0,"",Resultados!I33-(Resultados!H33)) -> 10604 | K21: =IF(Resultados!J33=0,"",Resultados!J33) -> 10796 | L21: =IF(Resultados!K33=0,"",Resultados!K33-(Resultados!J33)) -> 14121 | M21: =IF(Resultados!L33=0,"",Resultados!L33-(Resultados!K33)) | N21: =IF(Resultados!M33=0,"",Resultados!M33-(Resultados!L33))
B22: Flujo neto de operacion | C22: =IF(C11=0,"",C11) -> 20922 | D22: =IF(D11=0,"",D11-(C11)) -> 45261 | E22: =IF(E11=0,"",E11-(D11)) -> 38237 | F22: =IF('Flujo de Caja'!E32=0,"",'Flujo de Caja'!E32-(E11)) -> 35246 | G22: =IF('Flujo de Caja'!F32=0,"",'Flujo de Caja'!F32) -> 39992 | H22: =IF('Flujo de Caja'!G32=0,"",'Flujo de Caja'!G32-('Flujo de Caja'!F32)) -> 35652 | I22: =IF('Flujo de Caja'!H32=0,"",'Flujo de Caja'!H32-('Flujo de Caja'!G32)) -> 44026 | J22: =IF('Flujo de Caja'!I32=0,"",'Flujo de Caja'!I32-('Flujo de Caja'!H32)) -> 32063 | K22: =IF('Flujo de Caja'!J32=0,"",'Flujo de Caja'!J32) -> 23453 | L22: =IF('Flujo de Caja'!K32=0,"",'Flujo de Caja'!K32-('Flujo de Caja'!J32)) -> 26968 | M22: =IF('Flujo de Caja'!L32=0,"",'Flujo de Caja'!L32-('Flujo de Caja'!K32)) | N22: =IF('Flujo de Caja'!M32=0,"",'Flujo de Caja'!M32-('Flujo de Caja'!L32))
B23: Capex (PP&E + intangibles) | C23: =IF(C12=0,"",C12) -> -13366 | D23: =IF(D12=0,"",D12-(C12)) -> -28812 | E23: =IF(E12=0,"",E12-(D12)) -> -21777 | F23: =IF('Flujo de Caja'!E35+'Flujo de Caja'!E36=0,"",'Flujo de Caja'!E35+'Flujo de Caja'!E36-(E12)) -> -24155 | G23: =IF('Flujo de Caja'!F35+'Flujo de Caja'!F36=0,"",'Flujo de Caja'!F35+'Flujo de Caja'!F36) -> -15231 | H23: =IF('Flujo de Caja'!G35+'Flujo de Caja'!G36=0,"",'Flujo de Caja'!G35+'Flujo de Caja'!G36-('Flujo de Caja'!F35+'Flujo de Caja'!F36)) -> -26308 | I23: =IF('Flujo de Caja'!H35+'Flujo de Caja'!H36=0,"",'Flujo de Caja'!H35+'Flujo de Caja'!H36-('Flujo de Caja'!G35+'Flujo de Caja'!G36)) -> -33241 | J23: =IF('Flujo de Caja'!I35+'Flujo de Caja'!I36=0,"",'Flujo de Caja'!I35+'Flujo de Caja'!I36-('Flujo de Caja'!H35+'Flujo de Caja'!H36)) -> -34533 | K23: =IF('Flujo de Caja'!J35+'Flujo de Caja'!J36=0,"",'Flujo de Caja'!J35+'Flujo de Caja'!J36) -> -15824 | L23: =IF('Flujo de Caja'!K35+'Flujo de Caja'!K36=0,"",'Flujo de Caja'!K35+'Flujo de Caja'!K36-('Flujo de Caja'!J35+'Flujo de Caja'!J36)) -> -21061 | M23: =IF('Flujo de Caja'!L35+'Flujo de Caja'!L36=0,"",'Flujo de Caja'!L35+'Flujo de Caja'!L36-('Flujo de Caja'!K35+'Flujo de Caja'!K36)) | N23: =IF('Flujo de Caja'!M35+'Flujo de Caja'!M36=0,"",'Flujo de Caja'!M35+'Flujo de Caja'!M36-('Flujo de Caja'!L35+'Flujo de Caja'!L36))
B25: Flujo de caja libre (operativo + capex) | C25: =IF(OR(C22="",C23=""),"",C22+C23) -> 7556 | D25: =IF(OR(D22="",D23=""),"",D22+D23) -> 16449 | E25: =IF(OR(E22="",E23=""),"",E22+E23) -> 16460 | F25: =IF(OR(F22="",F23=""),"",F22+F23) -> 11091 | G25: =IF(OR(G22="",G23=""),"",G22+G23) -> 24761 | H25: =IF(OR(H22="",H23=""),"",H22+H23) -> 9344 | I25: =IF(OR(I22="",I23=""),"",I22+I23) -> 10785 | J25: =IF(OR(J22="",J23=""),"",J22+J23) -> -2470 | ... N25: =IF(OR(N22="",N23=""),"",N22+N23)

Sheet Capital de Trabajo
B1: Electro Dunas S.A.A. - Capital de Trabajo
B2: Partidas operativas del Estado de Situacion Financiera, en miles de soles. Los dias se calculan sobre el periodo acumulado de cada columna.
B4: En miles de soles | C4: 2022 | D4: 2023 | E4: 2024 | F4: 1T 2025 | G4: 2T 2025 (6M) | H4: 3T 2025 (9M) | I4: 2025 | J4: 1T 2026 | K4: 2T 2026 (6M) | L4: 3T 2026 (9M) (proyectado) | M4: 2026 (proyectado) | N4: 1T 2027 (proyectado) | O4: 2T 2027 (6M) (proyectado) | P4: 3T 2027 (9M) (proyectado) | Q4: 2027 (proyectado)
B6: Cuentas por cobrar comerciales | C6: ='Situacion Financiera'!C7 -> 87655 | D6: ='Situacion Financiera'!D7 -> 84151 | E6: ='Situacion Financiera'!E7 -> 86431 | F6: ='Situacion Financiera'!F7 -> 85574 | G6: ='Situacion Financiera'!G7 -> 79021 | H6: ='Situacion Financiera'!H7 -> 77588 | I6: ='Situacion Financiera'!I7 -> 81197 | J6: ='Situacion Financiera'!J7 -> 82127 | ... Q6: ='Situacion Financiera'!Q7 -> 0
B7: Otras cuentas por cobrar operativas (relacionadas + otras) | C7: ='Situacion Financiera'!C8+'Situacion Financiera'!C9 -> 47121 | D7: ='Situacion Financiera'!D8+'Situacion Financiera'!D9 -> 5594 | E7: ='Situacion Financiera'!E8+'Situacion Financiera'!E9 -> 30070 | F7: ='Situacion Financiera'!F8+'Situacion Financiera'!F9 -> 30179 | G7: ='Situacion Financiera'!G8+'Situacion Financiera'!G9 -> 29875 | H7: ='Situacion Financiera'!H8+'Situacion Financiera'!H9 -> 20371 | I7: ='Situacion Financiera'!I8+'Situacion Financiera'!I9 -> 18571 | J7: ='Situacion Financiera'!J8+'Situacion Financiera'!J9 -> 18244 | ... Q7: ='Situacion Financiera'!Q8+'Situacion Financiera'!Q9 -> 0
B8: Inventarios | C8: ='Situacion Financiera'!C10 -> 4566 | D8: ='Situacion Financiera'!D10 -> 4795 | E8: ='Situacion Financiera'!E10 -> 6668 | F8: ='Situacion Financiera'!F10 -> 6912 | G8: ='Situacion Financiera'!G10 -> 8878 | H8: ='Situacion Financiera'!H10 -> 9069 | I8: ='Situacion Financiera'!I10 -> 11173 | J8: ='Situacion Financiera'!J10 -> 10608 | ... Q8: ='Situacion Financiera'!Q10 -> 0
B9: Total activo corriente operativo | C9: =C6+C7+C8 -> 139342 | D9: =D6+D7+D8 -> 94540 | E9: =E6+E7+E8 -> 123169 | F9: =F6+F7+F8 -> 122665 | G9: =G6+G7+G8 -> 117774 | H9: =H6+H7+H8 -> 107028 | I9: =I6+I7+I8 -> 110941 | J9: =J6+J7+J8 -> 110979 | ... Q9: =Q6+Q7+Q8 -> 0
B11: Cuentas por pagar comerciales | C11: ='Situacion Financiera'!C27 -> 53792 | D11: ='Situacion Financiera'!D27 -> 43989 | E11: ='Situacion Financiera'!E27 -> 52610 | F11: ='Situacion Financiera'!F27 -> 60056 | G11: ='Situacion Financiera'!G27 -> 51029 | H11: ='Situacion Financiera'!H27 -> 52162 | I11: ='Situacion Financiera'!I27 -> 70205 | J11: ='Situacion Financiera'!J27 -> 60850 | ... Q11: ='Situacion Financiera'!Q27 -> 0
B12: Otras cuentas por pagar operativas (relacionadas + otras + provisiones) | C12: ='Situacion Financiera'!C28+'Situacion Financiera'!C31+'Situacion Financiera'!C32 -> 19474 | D12: ='Situacion Financiera'!D28+'Situacion Financiera'!D31+'Situacion Financiera'!D32 -> 69453 | E12: ='Situacion Financiera'!E28+'Situacion Financiera'!E31+'Situacion Financiera'!E32 -> 23108 | F12: ='Situacion Financiera'!F28+'Situacion Financiera'!F31+'Situacion Financiera'!F32 -> 17936 | G12: ='Situacion Financiera'!G28+'Situacion Financiera'!G31+'Situacion Financiera'!G32 -> 44123 | H12: ='Situacion Financiera'!H28+'Situacion Financiera'!H31+'Situacion Financiera'!H32 -> 24402 | I12: ='Situacion Financiera'!I28+'Situacion Financiera'!I31+'Situacion Financiera'!I32 -> 19695 | J12: ='Situacion Financiera'!J28+'Situacion Financiera'!J31+'Situacion Financiera'!J32 -> 39353 | ... Q12: ='Situacion Financiera'!Q28+'Situacion Financiera'!Q31+'Situacion Financiera'!Q32 -> 0
B13: Total pasivo corriente operativo | C13: =C11+C12 -> 73266 | D13: =D11+D12 -> 113442 | E13: =E11+E12 -> 75718 | F13: =F11+F12 -> 77992 | G13: =G11+G12 -> 95152 | H13: =H11+H12 -> 76564 | I13: =I11+I12 -> 89900 | J13: =J11+J12 -> 100203 | ... Q13: =Q11+Q12 -> 0
B15: Capital de trabajo neto operativo | C15: =C9-C13 -> 66076 | D15: =D9-D13 -> -18902 | E15: =E9-E13 -> 47451 | F15: =F9-F13 -> 44673 | G15: =G9-G13 -> 22622 | H15: =H9-H13 -> 30464 | I15: =I9-I13 -> 21041 | J15: =J9-J13 -> 10776 | ... Q15: =Q9-Q13 -> 0
B16: Variacion vs. periodo anterior | D16: =IF(ISBLANK(C15),"",D15-C15) -> -84978 | E16: =IF(ISBLANK(D15),"",E15-D15) -> 66353 | F16: =IF(ISBLANK(E15),"",F15-E15) -> -2778 | G16: =IF(ISBLANK(F15),"",G15-F15) -> -22051 | H16: =IF(ISBLANK(G15),"",H15-G15) -> 7842 | I16: =IF(ISBLANK(H15),"",I15-H15) -> -9423 | J16: =IF(ISBLANK(I15),"",J15-I15) -> -10265 | K16: =IF(ISBLANK(J15),"",K15-J15) -> 5686 | ... Q16: =IF(ISBLANK(P15),"",Q15-P15) -> 0
B18: Dias de cobro (DSO) | C18: =IFERROR(C6/Resultados!C8*365,"") -> 65.483398 | D18: =IFERROR(D6/Resultados!D8*365,"") -> 56.800637 | E18: =IFERROR(E6/Resultados!E8*365,"") -> 55.295431 | F18: =IFERROR(F6/Resultados!F8*90,"") -> 49.954337 | G18: =IFERROR(G6/Resultados!G8*181,"") -> 48.135537 | H18: =IFERROR(H6/Resultados!H8*273,"") -> 48.669439 | I18: =IFERROR(I6/Resultados!I8*365,"") -> 50.973228 | J18: =IFERROR(J6/Resultados!J8*90,"") -> 49.270288 | K18: =IFERROR(K6/Resultados!K8*181,"") -> 51.259379 | L18: =IFERROR(L6/Resultados!L8*273,"") | M18: =IFERROR(M6/Resultados!M8*365,"") | N18: =IFERROR(N6/Resultados!N8*90,"") | O18: =IFERROR(O6/Resultados!O8*181,"") | P18: =IFERROR(P6/Resultados!P8*273,"") | Q18: =IFERROR(Q6/Resultados!Q8*365,"")
B19: Dias de inventario (DIO) | C19: =IFERROR(C8/-Resultados!C11*365,"") -> 5.1589387 | D19: =IFERROR(D8/-Resultados!D11*365,"") -> 4.837584 | E19: =IFERROR(E8/-Resultados!E11*365,"") -> 6.2926316 | F19: =IFERROR(F8/-Resultados!F11*90,"") -> 5.9943918 | G19: =IFERROR(G8/-Resultados!G11*181,"") -> 8.0544846 | H19: =IFERROR(H8/-Resultados!H11*273,"") -> 8.4708581 | I19: =IFERROR(I8/-Resultados!I11*365,"") -> 10.224989 | J19: =IFERROR(J8/-Resultados!J11*90,"") -> 8.9610572 | K19: =IFERROR(K8/-Resultados!K11*181,"") -> 12.340461 | L19: =IFERROR(L8/-Resultados!L11*273,"") | M19: =IFERROR(M8/-Resultados!M11*365,"") | N19: =IFERROR(N8/-Resultados!N11*90,"") | O19: =IFERROR(O8/-Resultados!O11*181,"") | P19: =IFERROR(P8/-Resultados!P11*273,"") | Q19: =IFERROR(Q8/-Resultados!Q11*365,"")
B20: Dias de pago (DPO) | C20: =IFERROR(C11/-Resultados!C11*365,"") -> 60.777405 | D20: =IFERROR(D11/-Resultados!D11*365,"") -> 44.379663 | E20: =IFERROR(E11/-Resultados!E11*365,"") -> 49.648373 | F20: =IFERROR(F11/-Resultados!F11*90,"") -> 52.083217 | G20: =IFERROR(G11/-Resultados!G11*181,"") -> 46.295595 | H20: =IFERROR(H11/-Resultados!H11*273,"") -> 48.721678 | I20: =IFERROR(I11/-Resultados!I11*365,"") -> 64.248222 | J20: =IFERROR(J11/-Resultados!J11*90,"") -> 51.402746 | K20: =IFERROR(K11/-Resultados!K11*181,"") -> 51.907117 | L20: =IFERROR(L11/-Resultados!L11*273,"") | M20: =IFERROR(M11/-Resultados!M11*365,"") | N20: =IFERROR(N11/-Resultados!N11*90,"") | O20: =IFERROR(O11/-Resultados!O11*181,"") | P20: =IFERROR(P11/-Resultados!P11*273,"") | Q20: =IFERROR(Q11/-Resultados!Q11*365,"")
B21: Ciclo de conversion de efectivo (DSO+DIO-DPO) | C21: =IFERROR(C18+C19-C20,"") -> 9.8649314 | D21: =IFERROR(D18+D19-D20,"") -> 17.258559 | E21: =IFERROR(E18+E19-E20,"") -> 11.93969 | F21: =IFERROR(F18+F19-F20,"") -> 3.8655122 | G21: =IFERROR(G18+G19-G20,"") -> 9.8944267 | H21: =IFERROR(H18+H19-H20,"") -> 8.418619 | I21: =IFERROR(I18+I19-I20,"") -> -3.0500047 | J21: =IFERROR(J18+J19-J20,"") -> 6.8285985 | ... Q21: =IFERROR(Q18+Q19-Q20,"")

Sheet Deuda
B1: Electro Dunas S.A.A. - Deuda Financiera
B2: Detalle de acreedores y vencimientos contractuales de los otros pasivos financieros, en miles de soles. Fuente: Nota 19 de los EEFF auditados e intermedios.
B4: Acreedor / instrumento | C4: Tipo | D4: Moneda | E4: Tasa de interes | F4: Tasa efectiva | G4: Vencimiento | H4: 2024 | I4: 2025 | J4: 2T 2026
B6: Deuda corriente
B7: Banco BBVA Peru | C7: Credito corto plazo | D7: Sol | E7: 0.0513 | F7: 0.0513 | G7: Noviembre 2025 | H7: 80000 | I7: 0 | J7: 0
B8: Bonos corporativos - Segunda emision | C8: Bono corporativo | D8: Sol | E8: 0.0275 | F8: 0.0289 | G8: Diciembre 2025 | H8: 65500 | I8: 0 | J8: 0
B9: Banco de Credito del Peru | C9: Credito corto plazo | D9: Sol | E9: 0.047 | F9: 0.047 | G9: Setiembre 2026 | H9: 0 | I9: 80000 | J9: 0
B10: Banco de Credito del Peru | C10: Credito corto plazo | D10: Sol | E10: 0.0471 | F10: 0.0471 | G10: Octubre 2026 | H10: 0 | I10: 25000 | J10: 0
B11: Banco BCI | C11: Credito corto plazo | D11: Sol | E11: 0.0471 | F11: 0.0471 | G11: Setiembre 2026 | H11: 0 | I11: 20000 | J11: 0
B12: Banco GNB | C12: Credito corto plazo | D12: Sol | E12: 0.047 | F12: 0.047 | G12: Marzo 2026 | H12: 0 | I12: 10000 | J12: 0
B13: Banco de Credito del Peru | C13: Credito corto plazo | D13: Sol | E13: 0.0443 | F13: 0.0443 | G13: Marzo 2027 | H13: 0 | I13: 0 | J13: 10000
B14: Banco de Credito del Peru | C14: Credito corto plazo | D14: Sol | E14: 0.0443 | F14: 0.0443 | G14: Abril 2027 | H14: 0 | I14: 0 | J14: 40000
B15: Banco Pichincha | C15: Credito corto plazo | D15: Sol | E15: 0.0452 | F15: 0.0452 | G15: Diciembre 2026 | H15: 0 | I15: 0 | J15: 20000
B16: Partida de corto plazo sin desagregar por acreedor | H16: 0 | I16: 0 | J16: 200000
B17: Subtotal principal | H17: =SUM(H7:H16) -> 145500 | I17: =SUM(I7:I16) -> 135000 | J17: =SUM(J7:J16) -> 270000
B18: Intereses por pagar | H18: 1205 | I18: 2453 | J18: 4547
B19: Costos de transaccion - bonos corporativos | H19: -189 | I19: -123 | J19: -126
B20: Total otros pasivos financieros corrientes | H20: =H17+H18+H19 -> 146516 | I20: =I17+I18+I19 -> 137330 | J20: =J17+J18+J19 -> 274421
B22: Deuda no corriente
B23: Banco BCI | C23: Credito mediano plazo | D23: Sol | E23: 0.0486 | F23: 0.0486 | G23: Junio 2027 | H23: 0 | I23: 100000 | J23: 0
B24: Bonos corporativos - Primera emision | C24: Bono corporativo | D24: Sol | E24: 0.0459 | F24: 0.0472 | G24: Diciembre 2030 | H24: 230500 | I24: 230500 | J24: 230500
B25: Subtotal principal | H25: =SUM(H23:H24) -> 230500 | I25: =SUM(I23:I24) -> 330500 | J25: =SUM(J23:J24) -> 230500
B26: Intereses por pagar | H26: 0 | I26: 396 | J26: 0
B27: Costos de transaccion - bonos corporativos | H27: -702 | I27: -579 | J27: -527
B28: Total otros pasivos financieros no corrientes | H28: =H25+H26+H27 -> 229798 | I28: =I25+I26+I27 -> 330317 | J28: =J25+J26+J27 -> 229973
B30: Deuda bruta total (corriente + no corriente) | H30: =H20+H28 -> 376314 | I30: =I20+I28 -> 467647 | J30: =J20+J28 -> 504394
B31: Control: Deuda total (hoja) - Deuda total (Situacion Financiera), debe ser 0 | H31: =H30-('Situacion Financiera'!E25+'Situacion Financiera'!E36) -> 0 | I31: =I30-('Situacion Financiera'!I25+'Situacion Financiera'!I36) -> 0 | J31: =J30-('Situacion Financiera'!K25+'Situacion Financiera'!K36) -> 0
B33: Vencimientos contractuales (Nota 19, literal c)
B34: 2025 | H34: 146633 | I34: 0 | J34: 0
B35: 2026 | H35: 0 | I35: 137330 | J35: 40580
B36: 2027 | H36: 0 | I36: 100396 | J36: 233841
B37: 2030 | H37: 229681 | I37: 229921 | J37: 229973
B38: Total vencimientos | H38: =SUM(H34:H37) -> 376314 | I38: =SUM(I34:I37) -> 467647 | J38: =SUM(J34:J37) -> 504394
B39: Control: Total vencimientos - Deuda bruta total, debe ser 0 | H39: =H38-H30 -> 0 | I39: =I38-I30 -> 0 | J39: =J38-J30 -> 0

Sheet Activo Fijo
B1: Electro Dunas S.A.A. - Activo Fijo
B2: Movimiento de propiedad, planta y equipo, activos por derecho de uso y activos intangibles, en miles de soles. Fuente: Notas 12, 13 y 14 de los EEFF auditados e intermedios.
B4: Propiedad, planta y equipo (Nota 12)
B5: Ano 2024
C6: Terrenos | D6: Edificios y otras construcciones | E6: Maquinaria y equipo | F6: Unidades de transporte | G6: Muebles y enseres | H6: Equipos diversos y de computo | I6: Unidades de reemplazo | J6: Obras en curso | K6: Total
B7: Saldo al inicio del periodo | C7: 15066 | D7: 48024 | E7: 636018 | F7: 12379 | G7: 2529 | H7: 20619 | I7: 6800 | J7: 70325 | K7: =SUM(C7:J7) -> 811760
B8: (+) Adiciones | C8: 0 | D8: 0 | E8: 7727 | F8: 0 | G8: 0 | H8: 0 | I8: 850 | J8: 86226 | K8: =SUM(C8:J8) -> 94803
B9: (+/-) Transferencias | C9: 0 | D9: 4072 | E9: 97108 | F9: 0 | G9: 80 | H9: 1049 | I9: -790 | J9: -101519 | K9: =SUM(C9:J9) -> 0
B10: (-) Bajas | C10: 0 | D10: -5 | E10: -6054 | F10: -553 | G10: 0 | H10: 0 | I10: -2 | J10: 0 | K10: =SUM(C10:J10) -> -6614
B11: Saldo al final del periodo (costo) | C11: =SUM(C7:C10) -> 15066 | D11: =SUM(D7:D10) -> 52091 | E11: =SUM(E7:E10) -> 734799 | F11: =SUM(F7:F10) -> 11826 | G11: =SUM(G7:G10) -> 2609 | H11: =SUM(H7:H10) -> 21668 | I11: =SUM(I7:I10) -> 6858 | J11: =SUM(J7:J10) -> 55032 | K11: =SUM(K7:K10) -> 899949
B13: Saldo al inicio del periodo | C13: 0 | D13: -14636 | E13: -202724 | F13: -7498 | G13: -1416 | H13: -11921 | I13: 0 | J13: 0 | K13: =SUM(C13:J13) -> -238195
B14: (-) Adiciones (depreciacion / amortizacion del periodo) | C14: 0 | D14: -1039 | E14: -24691 | F14: -852 | G14: -142 | H14: -1168 | I14: 0 | J14: 0 | K14: =SUM(C14:J14) -> -27892
B15: (+) Bajas | C15: 0 | D15: 4 | E15: 5017 | F15: 500 | G15: 0 | H15: 0 | I15: 0 | J15: 0 | K15: =SUM(C15:J15) -> 5521
B16: Saldo al final del periodo (depreciacion / amortizacion acumulada) | C16: =SUM(C13:C15) -> 0 | D16: =SUM(D13:D15) -> -15671 | E16: =SUM(E13:E15) -> -222398 | F16: =SUM(F13:F15) -> -7850 | G16: =SUM(G13:G15) -> -1558 | H16: =SUM(H13:H15) -> -13089 | I16: =SUM(I13:I15) -> 0 | J16: =SUM(J13:J15) -> 0 | K16: =SUM(K13:K15) -> -260566
B18: Valor neto en libros | C18: =C11+C16 -> 15066 | D18: =D11+D16 -> 36420 | E18: =E11+E16 -> 512401 | F18: =F11+F16 -> 3976 | G18: =G11+G16 -> 1051 | H18: =H11+H16 -> 8579 | I18: =I11+I16 -> 6858 | J18: =J11+J16 -> 55032 | K18: =K11+K16 -> 639383
B19: Control: valor neto (hoja) - PP&E (Situacion Financiera), debe ser 0 | K19: =K18-'Situacion Financiera'!E17 -> 0
B21: Ano 2025
C22: Terrenos | D22: Edificios y otras construcciones | E22: Maquinaria y equipo | F22: Unidades de transporte | G22: Muebles y enseres | H22: Equipos diversos y de computo | I22: Unidades de reemplazo | J22: Obras en curso | K22: Total
B23: Saldo al inicio del periodo | C23: 15066 | D23: 52091 | E23: 734799 | F23: 11826 | G23: 2609 | H23: 21668 | I23: 6858 | J23: 55032 | K23: =SUM(C23:J23) -> 899949
B24: (+) Adiciones | C24: 43 | D24: 0 | E24: 6865 | F24: 0 | G24: 0 | H24: 0 | I24: 4160 | J24: 110507 | K24: =SUM(C24:J24) -> 121575
B25: (+/-) Transferencias | C25: 0 | D25: 214 | E25: 45499 | F25: 0 | G25: 239 | H25: 2244 | I25: -2275 | J25: -45921 | K25: =SUM(C25:J25) -> 0
B26: (-) Bajas | C26: 0 | D26: 0 | E26: -9996 | F26: 0 | G26: -9 | H26: -141 | I26: 0 | J26: 0 | K26: =SUM(C26:J26) -> -10146
B27: Saldo al final del periodo (costo) | C27: =SUM(C23:C26) -> 15109 | D27: =SUM(D23:D26) -> 52305 | E27: =SUM(E23:E26) -> 777167 | F27: =SUM(F23:F26) -> 11826 | G27: =SUM(G23:G26) -> 2839 | H27: =SUM(H23:H26) -> 23771 | I27: =SUM(I23:I26) -> 8743 | J27: =SUM(J23:J26) -> 119618 | K27: =SUM(K23:K26) -> 1011378
B29: Saldo al inicio del periodo | C29: 0 | D29: -15671 | E29: -222398 | F29: -7850 | G29: -1558 | H29: -13089 | I29: 0 | J29: 0 | K29: =SUM(C29:J29) -> -260566
B30: (-) Adiciones (depreciacion / amortizacion del periodo) | C30: 0 | D30: -1052 | E30: -26525 | F30: -834 | G30: -142 | H30: -1139 | I30: 0 | J30: 0 | K30: =SUM(C30:J30) -> -29692
B31: (+) Bajas | C31: 0 | D31: 0 | E31: 9174 | F31: 0 | G31: 9 | H31: 123 | I31: 0 | J31: 0 | K31: =SUM(C31:J31) -> 9306
B32: Saldo al final del periodo (depreciacion / amortizacion acumulada) | C32: =SUM(C29:C31) -> 0 | D32: =SUM(D29:D31) -> -16723 | E32: =SUM(E29:E31) -> -239749 | F32: =SUM(F29:F31) -> -8684 | G32: =SUM(G29:G31) -> -1691 | H32: =SUM(H29:H31) -> -14105 | I32: =SUM(I29:I31) -> 0 | J32: =SUM(J29:J31) -> 0 | K32: =SUM(K29:K31) -> -280952
B34: Valor neto en libros | C34: =C27+C32 -> 15109 | D34: =D27+D32 -> 35582 | E34: =E27+E32 -> 537418 | F34: =F27+F32 -> 3142 | G34: =G27+G32 -> 1148 | H34: =H27+H32 -> 9666 | I34: =I27+I32 -> 8743 | J34: =J27+J32 -> 119618 | K34: =K27+K32 -> 730426
B35: Control: valor neto (hoja) - PP&E (Situacion Financiera), debe ser 0 | K35: =K34-'Situacion Financiera'!I17 -> 0
B37: 6 meses terminados el 30 de junio de 2026
C38: Terrenos | D38: Edificios y otras construcciones | E38: Maquinaria y equipo | F38: Unidades de transporte | G38: Muebles y enseres | H38: Equipos diversos y de computo | I38: Unidades de reemplazo | J38: Obras en curso | K38: Total
B39: Saldo al inicio del periodo | C39: 15109 | D39: 52305 | E39: 777167 | F39: 11826 | G39: 2839 | H39: 23771 | I39: 8743 | J39: 119618 | K39: =SUM(C39:J39) -> 1011378
B40: (+) Adiciones | C40: 156 | D40: 0 | E40: 2165 | F40: 0 | G40: 0 | H40: 72 | I40: -2529 | J40: 47793 | K40: =SUM(C40:J40) -> 47657
B41: (+/-) Transferencias | C41: 0 | D41: 2731 | E41: 24885 | F41: 0 | G41: 20 | H41: 1039 | I41: -805 | J41: -27870 | K41: =SUM(C41:J41) -> 0
B42: (-) Bajas | C42: 0 | D42: 0 | E42: -2401 | F42: -81 | G42: 0 | H42: 0 | I42: 0 | J42: 0 | K42: =SUM(C42:J42) -> -2482
B43: Saldo al final del periodo (costo) | C43: =SUM(C39:C42) -> 15265 | D43: =SUM(D39:D42) -> 55036 | E43: =SUM(E39:E42) -> 801816 | F43: =SUM(F39:F42) -> 11745 | G43: =SUM(G39:G42) -> 2859 | H43: =SUM(H39:H42) -> 24882 | I43: =SUM(I39:I42) -> 5409 | J43: =SUM(J39:J42) -> 139541 | K43: =SUM(K39:K42) -> 1056553
B45: Saldo al inicio del periodo | C45: 0 | D45: -16723 | E45: -239749 | F45: -8684 | G45: -1691 | H45: -14105 | I45: 0 | J45: 0 | K45: =SUM(C45:J45) -> -280952
B46: (-) Adiciones (depreciacion / amortizacion del periodo) | C46: 0 | D46: -653 | E46: -13848 | F46: -357 | G46: -78 | H46: -631 | I46: 0 | J46: 0 | K46: =SUM(C46:J46) -> -15567
B47: (+) Bajas | C47: 0 | D47: 0 | E47: 1825 | F47: 59 | G47: 0 | H47: 0 | I47: 0 | J47: 0 | K47: =SUM(C47:J47) -> 1884
B48: Saldo al final del periodo (depreciacion / amortizacion acumulada) | C48: =SUM(C45:C47) -> 0 | D48: =SUM(D45:D47) -> -17376 | E48: =SUM(E45:E47) -> -251772 | F48: =SUM(F45:F47) -> -8982 | G48: =SUM(G45:G47) -> -1769 | H48: =SUM(H45:H47) -> -14736 | I48: =SUM(I45:I47) -> 0 | J48: =SUM(J45:J47) -> 0 | K48: =SUM(K45:K47) -> -294635
...

Sheet Indicadores
B1: Electro Dunas S.A.A. - Indicadores Financieros
B2: Ratios de liquidez, apalancamiento, cobertura y rentabilidad. El EBITDA y la utilidad neta de las columnas trimestrales se anualizan sumando los cuatro trimestres aislados moviles de la hoja Trimestres (LTM). En miles de soles salvo donde se indique.
B4: En miles de soles | C4: 2022 | D4: 2023 | E4: 2024 | F4: 1T 2025 | G4: 2T 2025 (6M) | H4: 3T 2025 (9M) | I4: 2025 | J4: 1T 2026 | K4: 2T 2026 (6M) | L4: 3T 2026 (9M) (proyectado) | M4: 2026 (proyectado) | N4: 1T 2027 (proyectado) | O4: 2T 2027 (6M) (proyectado) | P4: 3T 2027 (9M) (proyectado) | Q4: 2027 (proyectado)
B6: Liquidez
B7: Ratio corriente | C7: =IFERROR('Situacion Financiera'!C12/'Situacion Financiera'!C33,"") -> 1.0974949 | D7: =IFERROR('Situacion Financiera'!D12/'Situacion Financiera'!D33,"") -> 0.66433093 | E7: =IFERROR('Situacion Financiera'!E12/'Situacion Financiera'!E33,"") -> 0.51934327 | F7: =IFERROR('Situacion Financiera'!F12/'Situacion Financiera'!F33,"") -> 0.49999293 | G7: =IFERROR('Situacion Financiera'!G12/'Situacion Financiera'!G33,"") -> 0.46713811 | H7: =IFERROR('Situacion Financiera'!H12/'Situacion Financiera'!H33,"") -> 0.40589742 | I7: =IFERROR('Situacion Financiera'!I12/'Situacion Financiera'!I33,"") -> 0.51915201 | J7: =IFERROR('Situacion Financiera'!J12/'Situacion Financiera'!J33,"") -> 0.47549584 | ... Q7: =IFERROR('Situacion Financiera'!Q12/'Situacion Financiera'!Q33,"")
B8: Prueba acida (efectivo + CxC comerciales / pasivo corriente) | C8: =IFERROR(('Situacion Financiera'!C6+'Situacion Financiera'!C7)/'Situacion Financiera'!C33,"") -> 0.71923809 | D8: =IFERROR(('Situacion Financiera'!D6+'Situacion Financiera'!D7)/'Situacion Financiera'!D33,"") -> 0.58090445 | E8: =IFERROR(('Situacion Financiera'!E6+'Situacion Financiera'!E7)/'Situacion Financiera'!E33,"") -> 0.36072696 | F8: =IFERROR(('Situacion Financiera'!F6+'Situacion Financiera'!F7)/'Situacion Financiera'!F33,"") -> 0.34980739 | G8: =IFERROR(('Situacion Financiera'!G6+'Situacion Financiera'!G7)/'Situacion Financiera'!G33,"") -> 0.33285759 | H8: =IFERROR(('Situacion Financiera'!H6+'Situacion Financiera'!H7)/'Situacion Financiera'!H33,"") -> 0.30286374 | I8: =IFERROR(('Situacion Financiera'!I6+'Situacion Financiera'!I7)/'Situacion Financiera'!I33,"") -> 0.38775332 | J8: =IFERROR(('Situacion Financiera'!J6+'Situacion Financiera'!J7)/'Situacion Financiera'!J33,"") -> 0.35304011 | ... Q8: =IFERROR(('Situacion Financiera'!Q6+'Situacion Financiera'!Q7)/'Situacion Financiera'!Q33,"")
B10: Endeudamiento y apalancamiento
B11: Deuda financiera bruta | C11: ='Situacion Financiera'!C25+'Situacion Financiera'!C36 -> 334972 | D11: ='Situacion Financiera'!D25+'Situacion Financiera'!D36 -> 316336 | E11: ='Situacion Financiera'!E25+'Situacion Financiera'!E36 -> 376314 | F11: ='Situacion Financiera'!F25+'Situacion Financiera'!F36 -> 387884 | G11: ='Situacion Financiera'!G25+'Situacion Financiera'!G36 -> 412020 | H11: ='Situacion Financiera'!H25+'Situacion Financiera'!H36 -> 424414 | I11: ='Situacion Financiera'!I25+'Situacion Financiera'!I36 -> 467647 | J11: ='Situacion Financiera'!J25+'Situacion Financiera'!J36 -> 472610 | ... Q11: ='Situacion Financiera'!Q25+'Situacion Financiera'!Q36 -> 0
B12: Deuda financiera neta | C12: =C11-'Situacion Financiera'!C6 -> 316484 | D12: =D11-'Situacion Financiera'!D6 -> 300177 | E12: =E11-'Situacion Financiera'!E6 -> 366182 | F12: =F11-'Situacion Financiera'!F6 -> 374480 | G12: =G11-'Situacion Financiera'!G6 -> 382828 | H12: =H11-'Situacion Financiera'!H6 -> 404694 | I12: =I11-'Situacion Financiera'!I6 -> 442137 | J12: =J11-'Situacion Financiera'!J6 -> 454397 | ... Q12: =Q11-'Situacion Financiera'!Q6 -> 0
B13: EBITDA LTM (ultimos 12 meses) | C13: =Resultados!C24 -> 147638 | D13: =Resultados!D24 -> 156268 | E13: =Resultados!E24 -> 168687 | F13: =IF(OR(Trimestres!D20="",Trimestres!E20="",Trimestres!F20="",Trimestres!G20=""),"",Trimestres!D20+Trimestres!E20+Trimestres!F20+Trimestres!G20) -> 171554 | G13: =IF(OR(Trimestres!E20="",Trimestres!F20="",Trimestres!G20="",Trimestres!H20=""),"",Trimestres!E20+Trimestres!F20+Trimestres!G20+Trimestres!H20) -> 172860 | H13: =IF(OR(Trimestres!F20="",Trimestres!G20="",Trimestres!H20="",Trimestres!I20=""),"",Trimestres!F20+Trimestres!G20+Trimestres!H20+Trimestres!I20) -> 177251 | I13: =Resultados!I24 -> 171271 | J13: =IF(OR(Trimestres!H20="",Trimestres!I20="",Trimestres!J20="",Trimestres!K20=""),"",Trimestres!H20+Trimestres!I20+Trimestres!J20+Trimestres!K20) -> 163663 | K13: =IF(OR(Trimestres!I20="",Trimestres!J20="",Trimestres!K20="",Trimestres!L20=""),"",Trimestres!I20+Trimestres!J20+Trimestres!K20+Trimestres!L20) -> 162641 | L13: =IF(OR(Trimestres!J20="",Trimestres!K20="",Trimestres!L20="",Trimestres!M20=""),"",Trimestres!J20+Trimestres!K20+Trimestres!L20+Trimestres!M20) | M13: =Resultados!M24 -> 0 | Q13: =Resultados!Q24 -> 0
B14: Deuda bruta / EBITDA LTM | C14: =IFERROR(C11/C13,"") -> 2.2688739 | D14: =IFERROR(D11/D13,"") -> 2.0243172 | E14: =IFERROR(E11/E13,"") -> 2.2308417 | F14: =IFERROR(F11/F13,"") -> 2.2610024 | G14: =IFERROR(G11/G13,"") -> 2.3835474 | H14: =IFERROR(H11/H13,"") -> 2.3944237 | I14: =IFERROR(I11/I13,"") -> 2.7304506 | J14: =IFERROR(J11/J13,"") -> 2.8877022 | ... Q14: =IFERROR(Q11/Q13,"")
B15: Deuda neta / EBITDA LTM | C15: =IFERROR(C12/C13,"") -> 2.1436487 | D15: =IFERROR(D12/D13,"") -> 1.9209115 | E15: =IFERROR(E12/E13,"") -> 2.1707778 | F15: =IFERROR(F12/F13,"") -> 2.1828695 | G15: =IFERROR(G12/G13,"") -> 2.2146708 | H15: =IFERROR(H12/H13,"") -> 2.2831691 | I15: =IFERROR(I12/I13,"") -> 2.5815053 | J15: =IFERROR(J12/J13,"") -> 2.7764186 | ... Q15: =IFERROR(Q12/Q13,"")
B16: Deuda bruta / Patrimonio | C16: =IFERROR(C11/'Situacion Financiera'!C51,"") -> 1.7142448 | D16: =IFERROR(D11/'Situacion Financiera'!D51,"") -> 1.5343082 | E16: =IFERROR(E11/'Situacion Financiera'!E51,"") -> 1.8033843 | F16: =IFERROR(F11/'Situacion Financiera'!F51,"") -> 1.8241261 | G16: =IFERROR(G11/'Situacion Financiera'!G51,"") -> 2.0177574 | H16: =IFERROR(H11/'Situacion Financiera'!H51,"") -> 1.935895 | I16: =IFERROR(I11/'Situacion Financiera'!I51,"") -> 2.249828 | J16: =IFERROR(J11/'Situacion Financiera'!J51,"") -> 2.3364726 | ... Q16: =IFERROR(Q11/'Situacion Financiera'!Q51,"")
B17: Pasivo total / Patrimonio | C17: =IFERROR('Situacion Financiera'!C44/'Situacion Financiera'!C51,"") -> 3.1648269 | D17: =IFERROR('Situacion Financiera'!D44/'Situacion Financiera'!D51,"") -> 3.0063926 | E17: =IFERROR('Situacion Financiera'!E44/'Situacion Financiera'!E51,"") -> 3.4387864 | F17: =IFERROR('Situacion Financiera'!F44/'Situacion Financiera'!F51,"") -> 3.4009622 | G17: =IFERROR('Situacion Financiera'!G44/'Situacion Financiera'!G51,"") -> 3.6953824 | H17: =IFERROR('Situacion Financiera'!H44/'Situacion Financiera'!H51,"") -> 3.3695732 | I17: =IFERROR('Situacion Financiera'!I44/'Situacion Financiera'!I51,"") -> 3.7748859 | J17: =IFERROR('Situacion Financiera'!J44/'Situacion Financiera'!J51,"") -> 3.9107997 | ... Q17: =IFERROR('Situacion Financiera'!Q44/'Situacion Financiera'!Q51,"")
B18: Pasivo total / Activo total | C18: =IFERROR('Situacion Financiera'!C44/'Situacion Financiera'!C21,"") -> 0.75989398 | D18: =IFERROR('Situacion Financiera'!D44/'Situacion Financiera'!D21,"") -> 0.7503989 | E18: =IFERROR('Situacion Financiera'!E44/'Situacion Financiera'!E21,"") -> 0.7747132 | F18: =IFERROR('Situacion Financiera'!F44/'Situacion Financiera'!F21,"") -> 0.77277696 | G18: =IFERROR('Situacion Financiera'!G44/'Situacion Financiera'!G21,"") -> 0.7870248 | H18: =IFERROR('Situacion Financiera'!H44/'Situacion Financiera'!H21,"") -> 0.77114469 | I18: =IFERROR('Situacion Financiera'!I44/'Situacion Financiera'!I21,"") -> 0.79057091 | J18: =IFERROR('Situacion Financiera'!J44/'Situacion Financiera'!J21,"") -> 0.79636718 | ... Q18: =IFERROR('Situacion Financiera'!Q44/'Situacion Financiera'!Q21,"")
B20: Cobertura (cifras del periodo acumulado, no anualizadas)
B21: EBIT / Gastos financieros | C21: =IFERROR(Resultados!C21/-Resultados!C28,"") -> 3.6732041 | D21: =IFERROR(Resultados!D21/-Resultados!D28,"") -> 3.8763845 | E21: =IFERROR(Resultados!E21/-Resultados!E28,"") -> 3.9746968 | F21: =IFERROR(Resultados!F21/-Resultados!F28,"") -> 5.0277861 | G21: =IFERROR(Resultados!G21/-Resultados!G28,"") -> 4.0256626 | H21: =IFERROR(Resultados!H21/-Resultados!H28,"") -> 3.8529781 | I21: =IFERROR(Resultados!I21/-Resultados!I28,"") -> 3.5088591 | J21: =IFERROR(Resultados!J21/-Resultados!J28,"") -> 3.298925 | ... Q21: =IFERROR(Resultados!Q21/-Resultados!Q28,"")
B22: EBITDA / Gastos financieros | C22: =IFERROR(Resultados!C24/-Resultados!C28,"") -> 5.5790349 | D22: =IFERROR(Resultados!D24/-Resultados!D28,"") -> 5.7887757 | E22: =IFERROR(Resultados!E24/-Resultados!E28,"") -> 5.8792346 | F22: =IFERROR(Resultados!F24/-Resultados!F28,"") -> 7.2644159 | G22: =IFERROR(Resultados!G24/-Resultados!G28,"") -> 5.9681809 | H22: =IFERROR(Resultados!H24/-Resultados!H28,"") -> 5.8137463 | I22: =IFERROR(Resultados!I24/-Resultados!I28,"") -> 5.4579669 | J22: =IFERROR(Resultados!J24/-Resultados!J28,"") -> 5.3127833 | ... Q22: =IFERROR(Resultados!Q24/-Resultados!Q28,"")
B24: Rentabilidad
B25: Margen bruto | C25: =IFERROR(Resultados!C12/Resultados!C8,"") -> 0.33880426 | D25: =IFERROR(Resultados!D12/Resultados!D8,"") -> 0.33095702 | E25: =IFERROR(Resultados!E12/Resultados!E8,"") -> 0.32207291 | F25: =IFERROR(Resultados!F12/Resultados!F8,"") -> 0.32688391 | G25: =IFERROR(Resultados!G12/Resultados!G8,"") -> 0.32857008 | H25: =IFERROR(Resultados!H12/Resultados!H8,"") -> 0.32842615 | I25: =IFERROR(Resultados!I12/Resultados!I8,"") -> 0.31402375 | J25: =IFERROR(Resultados!J12/Resultados!J8,"") -> 0.28981189 | ... Q25: =IFERROR(Resultados!Q12/Resultados!Q8,"")
B26: Margen operativo (EBIT) | C26: =IFERROR(Resultados!C21/Resultados!C8,"") -> 0.19895084 | D26: =IFERROR(Resultados!D21/Resultados!D8,"") -> 0.19351349 | E26: =IFERROR(Resultados!E21/Resultados!E8,"") -> 0.19989028 | F26: =IFERROR(Resultados!F21/Resultados!F8,"") -> 0.21829881 | G26: =IFERROR(Resultados!G21/Resultados!G8,"") -> 0.20906252 | H26: =IFERROR(Resultados!H21/Resultados!H8,"") -> 0.20467496 | I26: =IFERROR(Resultados!I21/Resultados!I8,"") -> 0.1893774 | J26: =IFERROR(Resultados!J21/Resultados!J8,"") -> 0.16978629 | ... Q26: =IFERROR(Resultados!Q21/Resultados!Q8,"")
B27: Margen EBITDA | C27: =IFERROR(Resultados!C24/Resultados!C8,"") -> 0.30217588 | D27: =IFERROR(Resultados!D24/Resultados!D8,"") -> 0.28898222 | E27: =IFERROR(Resultados!E24/Resultados!E8,"") -> 0.29567081 | F27: =IFERROR(Resultados!F24/Resultados!F8,"") -> 0.31540986 | G27: =IFERROR(Resultados!G24/Resultados!G8,"") -> 0.30994225 | H27: =IFERROR(Resultados!H24/Resultados!H8,"") -> 0.3088334 | I27: =IFERROR(Resultados!I24/Resultados!I8,"") -> 0.29457312 | J27: =IFERROR(Resultados!J24/Resultados!J8,"") -> 0.27343385 | ... Q27: =IFERROR(Resultados!Q24/Resultados!Q8,"")
B28: Margen neto | C28: =IFERROR(Resultados!C33/Resultados!C8,"") -> 0.10978278 | D28: =IFERROR(Resultados!D33/Resultados!D8,"") -> 0.10660135 | E28: =IFERROR(Resultados!E33/Resultados!E8,"") -> 0.10807277 | F28: =IFERROR(Resultados!F33/Resultados!F8,"") -> 0.1372605 | G28: =IFERROR(Resultados!G33/Resultados!G8,"") -> 0.12693851 | H28: =IFERROR(Resultados!H33/Resultados!H8,"") -> 0.12121679 | I28: =IFERROR(Resultados!I33/Resultados!I8,"") -> 0.10897267 | J28: =IFERROR(Resultados!J33/Resultados!J8,"") -> 0.071964698 | ... Q28: =IFERROR(Resultados!Q33/Resultados!Q8,"")
B30: Utilidad neta LTM (ultimos 12 meses) | C30: =Resultados!C33 -> 53638 | D30: =Resultados!D33 -> 57645 | E30: =Resultados!E33 -> 61658 | F30: =IF(OR(Trimestres!D21="",Trimestres!E21="",Trimestres!F21="",Trimestres!G21=""),"",Trimestres!D21+Trimestres!E21+Trimestres!F21+Trimestres!G21) -> 64573 | G30: =IF(OR(Trimestres!E21="",Trimestres!F21="",Trimestres!G21="",Trimestres!H21=""),"",Trimestres!E21+Trimestres!F21+Trimestres!G21+Trimestres!H21) -> 66713 | H30: =IF(OR(Trimestres!F21="",Trimestres!G21="",Trimestres!H21="",Trimestres!I21=""),"",Trimestres!F21+Trimestres!G21+Trimestres!H21+Trimestres!I21) -> 66764 | I30: =Resultados!I33 -> 63359 | J30: =IF(OR(Trimestres!H21="",Trimestres!I21="",Trimestres!J21="",Trimestres!K21=""),"",Trimestres!H21+Trimestres!I21+Trimestres!J21+Trimestres!K21) -> 52993 | K30: =IF(OR(Trimestres!I21="",Trimestres!J21="",Trimestres!K21="",Trimestres!L21=""),"",Trimestres!I21+Trimestres!J21+Trimestres!K21+Trimestres!L21) -> 50558 | L30: =IF(OR(Trimestres!J21="",Trimestres!K21="",Trimestres!L21="",Trimestres!M21=""),"",Trimestres!J21+Trimestres!K21+Trimestres!L21+Trimestres!M21) | M30: =Resultados!M33 -> 0 | Q30: =Resultados!Q33 -> 0
B31: ROE (Utilidad neta LTM / Patrimonio) | C31: =IFERROR(C30/'Situacion Financiera'!C51,"") -> 0.27449656 | D31: =IFERROR(D30/'Situacion Financiera'!D51,"") -> 0.27959258 | E31: =IFERROR(E30/'Situacion Financiera'!E51,"") -> 0.29547949 | F31: =IFERROR(F30/'Situacion Financiera'!F51,"") -> 0.30367145 | G31: =IFERROR(G30/'Situacion Financiera'!G51,"") -> 0.32670901 | H31: =IFERROR(H30/'Situacion Financiera'!H51,"") -> 0.30453306 | I31: =IFERROR(I30/'Situacion Financiera'!I51,"") -> 0.30481721 | J31: =IFERROR(J30/'Situacion Financiera'!J51,"") -> 0.26198492 | ... Q31: =IFERROR(Q30/'Situacion Financiera'!Q51,"")
B32: ROA (Utilidad neta LTM / Activo total) | C32: =IFERROR(C30/'Situacion Financiera'!C21,"") -> 0.065908275 | D32: =IFERROR(D30/'Situacion Financiera'!D21,"") -> 0.069786615 | E32: =IFERROR(E30/'Situacion Financiera'!E21,"") -> 0.066567629 | F32: =IFERROR(F30/'Situacion Financiera'!F21,"") -> 0.069001149 | G32: =IFERROR(G30/'Situacion Financiera'!G21,"") -> 0.069580917 | H32: =IFERROR(H30/'Situacion Financiera'!H21,"") -> 0.069694006 | I32: =IFERROR(I30/'Situacion Financiera'!I21,"") -> 0.06383759 | J32: =IFERROR(J30/'Situacion Financiera'!J21,"") -> 0.053348729 | ... Q32: =IFERROR(Q30/'Situacion Financiera'!Q21,"")
